### 04. 에러 처리하기

---

- `Error`와 `Exception`
  - `Error`는 개발자가 예상할 수 있는 케이스이고, `Exception`은 개발자가 전혀 예상할 수 없는 케이스를 의미함

<br>

- `Error`에 대해
  - Java에서는 Exception이라는 클래스가 존재하지만 JavaScript나 TypeScript에서는 Error라는 클래스가 존재함
  ```javascript
  const array = new Array(100000000000000000000);
  // RangeError: Invalid array length
  ```

<br>

- 에러 처리의 기본 (try, catch finally)

```typescript
// Error(Exception) Handling: try -> catch -> finally

function readFile(fileName: string): string {
  if (fileName === "not exist!") {
    throw new Error(`file not exist! ${fileName}`);
  }
  return "file contents";
}

function closeFile(fileName: string) {
  //
}

const fileName1 = "file";
console.log(readFile(fileName1));
// file contents
closeFile(fileName1);

const fileName2 = "not exist!";
// console.log(readFile(fileName2));
// Error: file not exist! not exist!
closeFile(fileName2);

// try - catch를 사용하면 프로그램이 죽지 않음.
// finally는 에러 발생 여부와 상관없이 마지막에 무조건 실행됨
try {
  console.log(readFile(fileName2));
} catch (e) {
  console.log(`catched!`);
} finally {
  closeFile(fileName2);
  console.log(`finally!`);
}
console.log("!!!");
// file contents
// catched!
// finally!
// !!!

function run() {
  const fileName = "not exist!";

  try {
    console.log(readFile(fileName));
  } catch (e) {
    console.log(`catched!`);
    return;
  } finally {
    // 에러가 발생하면 catch에서 로직을 수행하고 return하여도 finally의 로직은 수행됨
    closeFile(fileName);
    console.log(`finally!`);
  }

  // 에러가 발생하면 catch에서 로직을 수행하고 return했기 때문에 아래의 로직이 수행되지 않음
  closeFile(fileName);
  console.log(`closed!`);
}

run();
// catched!
// finally!
```

<br>

- 우아하게 에러를 처리하는 방법

```typescript
class NetworkClient {
  tryConnect(): void {
    throw new Error("no network!");
  }
}

class UserService {
  constructor(private client: NetworkClient) {}

  login() {
    this.client.tryConnect();
    // 여기서는 try-catch 문을 사용해서 유의미한 에러 핸들링을 할 수 없음
    // App 클래스는 에러가 발생했는지, 어떤 일이 발생했는지 전혀 알 수 없음
    // 따라서 여기서 try-catch 문을 사용하지 않는 것이 좋음. 처리할 수 있는 곳에서 사용하는 것이 좋음
    // try {
    // } catch (e) {
    //   console.log("catced!");
    // }
  }
}

const client = new NetworkClient();
const service = new UserService(client);
// service.login();
// Error: no network!

class App {
  constructor(private userService: UserService) {}

  run() {
    try {
      this.userService.login();
    } catch (e) {
      console.log("catched!");
      // show dialog to user
    }
  }
}

const app = new App(service);
app.run();
// catced!
```

<br>

- 막강한 Error State

```typescript
{
  type NetworkErrorState = {
    result: "fail";
    reason: "offline" | "down" | "timeout";
  };
  type SuccessState = {
    result: "success";
  };

  type ResultState = SuccessState | NetworkErrorState;

  class NetworkClient {
    tryConnect(): ResultState {
      return { result: "success" };
    }
  }

  class UserService {
    constructor(private client: NetworkClient) {}

    login() {
      this.client.tryConnect();
    }
  }

  const client = new NetworkClient();
  const service = new UserService(client);

  class App {
    constructor(private userService: UserService) {}

    run() {
      try {
        this.userService.login();
      } catch (error) {
        console.log("catched!");
        // try-catch에서 전달되는 error는 any타입이므로 아래의 로직을 수행할 수 없음
        // if (error instanceof OfflineError) {
        //
        // }
      }
    }
  }

  const app = new App(service);
  app.run();
  // catced!
}
```
